[2024-05-10T10:25:47.346+0000] {local_task_job_runner.py:120} INFO - ::group::Pre task execution logs
[2024-05-10T10:25:47.382+0000] {taskinstance.py:2076} INFO - Dependencies all met for dep_context=non-requeueable deps ti=<TaskInstance: ds_project.ds_task manual__2024-05-10T10:25:25.868760+00:00 [queued]>
[2024-05-10T10:25:47.394+0000] {taskinstance.py:2076} INFO - Dependencies all met for dep_context=requeueable deps ti=<TaskInstance: ds_project.ds_task manual__2024-05-10T10:25:25.868760+00:00 [queued]>
[2024-05-10T10:25:47.396+0000] {taskinstance.py:2306} INFO - Starting attempt 1 of 1
[2024-05-10T10:25:47.413+0000] {taskinstance.py:2330} INFO - Executing <Task(PythonOperator): ds_task> on 2024-05-10 10:25:25.868760+00:00
[2024-05-10T10:25:47.428+0000] {standard_task_runner.py:90} INFO - Running: ['***', 'tasks', 'run', 'ds_project', 'ds_task', 'manual__2024-05-10T10:25:25.868760+00:00', '--job-id', '49', '--raw', '--subdir', 'DAGS_FOLDER/test_dags.py', '--cfg-path', '/tmp/tmpnb4pw4sv']
[2024-05-10T10:25:47.430+0000] {standard_task_runner.py:91} INFO - Job 49: Subtask ds_task
[2024-05-10T10:25:47.437+0000] {logging_mixin.py:188} WARNING - /home/***/.local/lib/python3.12/site-packages/***/task/task_runner/standard_task_runner.py:61 DeprecationWarning: This process (pid=1451) is multi-threaded, use of fork() may lead to deadlocks in the child.
[2024-05-10T10:25:47.438+0000] {standard_task_runner.py:63} INFO - Started process 1468 to run task
[2024-05-10T10:25:47.692+0000] {task_command.py:426} INFO - Running <TaskInstance: ds_project.ds_task manual__2024-05-10T10:25:25.868760+00:00 [running]> on host 3514ccd847da
[2024-05-10T10:25:47.780+0000] {taskinstance.py:2648} INFO - Exporting env vars: AIRFLOW_CTX_DAG_OWNER='***' AIRFLOW_CTX_DAG_ID='ds_project' AIRFLOW_CTX_TASK_ID='ds_task' AIRFLOW_CTX_EXECUTION_DATE='2024-05-10T10:25:25.868760+00:00' AIRFLOW_CTX_TRY_NUMBER='1' AIRFLOW_CTX_DAG_RUN_ID='manual__2024-05-10T10:25:25.868760+00:00'
[2024-05-10T10:25:47.782+0000] {taskinstance.py:430} INFO - ::endgroup::
[2024-05-10T10:25:47.815+0000] {logging_mixin.py:188} INFO - Start
[2024-05-10T10:25:47.819+0000] {taskinstance.py:441} INFO - ::group::Post task execution logs
[2024-05-10T10:25:47.820+0000] {taskinstance.py:2905} ERROR - Task failed with exception
Traceback (most recent call last):
  File "/home/airflow/.local/lib/python3.12/site-packages/airflow/models/taskinstance.py", line 465, in _execute_task
    result = _execute_callable(context=context, **execute_callable_kwargs)
             ^^^^^^^^^^^^^^^^^^^^^^^^^^^^^^^^^^^^^^^^^^^^^^^^^^^^^^^^^^^^^
  File "/home/airflow/.local/lib/python3.12/site-packages/airflow/models/taskinstance.py", line 432, in _execute_callable
    return execute_callable(context=context, **execute_callable_kwargs)
           ^^^^^^^^^^^^^^^^^^^^^^^^^^^^^^^^^^^^^^^^^^^^^^^^^^^^^^^^^^^^
  File "/home/airflow/.local/lib/python3.12/site-packages/airflow/models/baseoperator.py", line 400, in wrapper
    return func(self, *args, **kwargs)
           ^^^^^^^^^^^^^^^^^^^^^^^^^^^
  File "/home/airflow/.local/lib/python3.12/site-packages/airflow/operators/python.py", line 235, in execute
    return_value = self.execute_callable()
                   ^^^^^^^^^^^^^^^^^^^^^^^
  File "/home/airflow/.local/lib/python3.12/site-packages/airflow/operators/python.py", line 252, in execute_callable
    return self.python_callable(*self.op_args, **self.op_kwargs)
           ^^^^^^^^^^^^^^^^^^^^^^^^^^^^^^^^^^^^^^^^^^^^^^^^^^^^^
  File "/opt/airflow/dags/test_dags.py", line 45, in ds_run_script
    main(paper_info_path, ref_info_path)
  File "/opt/airflow/dags/script.py", line 226, in main
    df_ref, df_pub, lat_lon_ciry = load_data()
                                   ^^^^^^^^^^^
  File "/opt/airflow/dags/script.py", line 157, in load_data
    lat_lon_ciry = pd.read_csv(get_path("/plugins/data_raw/worldcities.csv"))
                   ^^^^^^^^^^^^^^^^^^^^^^^^^^^^^^^^^^^^^^^^^^^^^^^^^^^^^^^^^^
  File "/home/airflow/.local/lib/python3.12/site-packages/pandas/io/parsers/readers.py", line 1026, in read_csv
    return _read(filepath_or_buffer, kwds)
           ^^^^^^^^^^^^^^^^^^^^^^^^^^^^^^^
  File "/home/airflow/.local/lib/python3.12/site-packages/pandas/io/parsers/readers.py", line 620, in _read
    parser = TextFileReader(filepath_or_buffer, **kwds)
             ^^^^^^^^^^^^^^^^^^^^^^^^^^^^^^^^^^^^^^^^^^
  File "/home/airflow/.local/lib/python3.12/site-packages/pandas/io/parsers/readers.py", line 1620, in __init__
    self._engine = self._make_engine(f, self.engine)
                   ^^^^^^^^^^^^^^^^^^^^^^^^^^^^^^^^^
  File "/home/airflow/.local/lib/python3.12/site-packages/pandas/io/parsers/readers.py", line 1880, in _make_engine
    self.handles = get_handle(
                   ^^^^^^^^^^^
  File "/home/airflow/.local/lib/python3.12/site-packages/pandas/io/common.py", line 873, in get_handle
    handle = open(
             ^^^^^
FileNotFoundError: [Errno 2] No such file or directory: '/plugins/data_raw/worldcities.csv'
[2024-05-10T10:25:47.841+0000] {taskinstance.py:1206} INFO - Marking task as FAILED. dag_id=ds_project, task_id=ds_task, run_id=manual__2024-05-10T10:25:25.868760+00:00, execution_date=20240510T102525, start_date=20240510T102547, end_date=20240510T102547
[2024-05-10T10:25:47.858+0000] {standard_task_runner.py:110} ERROR - Failed to execute job 49 for task ds_task ([Errno 2] No such file or directory: '/plugins/data_raw/worldcities.csv'; 1468)
[2024-05-10T10:25:47.894+0000] {local_task_job_runner.py:240} INFO - Task exited with return code 1
[2024-05-10T10:25:48.095+0000] {taskinstance.py:3498} INFO - 0 downstream tasks scheduled from follow-on schedule check
[2024-05-10T10:25:48.100+0000] {local_task_job_runner.py:222} INFO - ::endgroup::
