[2024-05-10T02:51:58.948+0000] {local_task_job_runner.py:120} INFO - ::group::Pre task execution logs
[2024-05-10T02:52:00.150+0000] {taskinstance.py:2076} INFO - Dependencies all met for dep_context=non-requeueable deps ti=<TaskInstance: test_project.scraping_data scheduled__2024-05-08T23:00:00+00:00 [queued]>
[2024-05-10T02:52:00.175+0000] {taskinstance.py:2076} INFO - Dependencies all met for dep_context=requeueable deps ti=<TaskInstance: test_project.scraping_data scheduled__2024-05-08T23:00:00+00:00 [queued]>
[2024-05-10T02:52:00.176+0000] {taskinstance.py:2306} INFO - Starting attempt 1 of 1
[2024-05-10T02:52:00.217+0000] {taskinstance.py:2330} INFO - Executing <Task(PythonOperator): scraping_data> on 2024-05-08 23:00:00+00:00
[2024-05-10T02:52:00.234+0000] {standard_task_runner.py:90} INFO - Running: ['***', 'tasks', 'run', 'test_project', 'scraping_data', 'scheduled__2024-05-08T23:00:00+00:00', '--job-id', '14', '--raw', '--subdir', 'DAGS_FOLDER/test_dags.py', '--cfg-path', '/tmp/tmpepuh0rro']
[2024-05-10T02:52:00.237+0000] {standard_task_runner.py:91} INFO - Job 14: Subtask scraping_data
[2024-05-10T02:52:00.248+0000] {logging_mixin.py:188} WARNING - /home/***/.local/lib/python3.12/site-packages/***/task/task_runner/standard_task_runner.py:61 DeprecationWarning: This process (pid=362) is multi-threaded, use of fork() may lead to deadlocks in the child.
[2024-05-10T02:52:00.254+0000] {standard_task_runner.py:63} INFO - Started process 376 to run task
[2024-05-10T02:52:00.477+0000] {task_command.py:426} INFO - Running <TaskInstance: test_project.scraping_data scheduled__2024-05-08T23:00:00+00:00 [running]> on host b0077577925f
[2024-05-10T02:52:00.659+0000] {taskinstance.py:2648} INFO - Exporting env vars: AIRFLOW_CTX_DAG_OWNER='***' AIRFLOW_CTX_DAG_ID='test_project' AIRFLOW_CTX_TASK_ID='scraping_data' AIRFLOW_CTX_EXECUTION_DATE='2024-05-08T23:00:00+00:00' AIRFLOW_CTX_TRY_NUMBER='1' AIRFLOW_CTX_DAG_RUN_ID='scheduled__2024-05-08T23:00:00+00:00'
[2024-05-10T02:52:00.661+0000] {taskinstance.py:430} INFO - ::endgroup::
[2024-05-10T02:52:00.935+0000] {taskinstance.py:441} INFO - ::group::Post task execution logs
[2024-05-10T02:52:00.937+0000] {taskinstance.py:2905} ERROR - Task failed with exception
Traceback (most recent call last):
  File "/home/airflow/.local/lib/python3.12/site-packages/urllib3/connection.py", line 198, in _new_conn
    sock = connection.create_connection(
           ^^^^^^^^^^^^^^^^^^^^^^^^^^^^^
  File "/home/airflow/.local/lib/python3.12/site-packages/urllib3/util/connection.py", line 60, in create_connection
    for res in socket.getaddrinfo(host, port, family, socket.SOCK_STREAM):
               ^^^^^^^^^^^^^^^^^^^^^^^^^^^^^^^^^^^^^^^^^^^^^^^^^^^^^^^^^^
  File "/usr/local/lib/python3.12/socket.py", line 963, in getaddrinfo
    for res in _socket.getaddrinfo(host, port, family, type, proto, flags):
               ^^^^^^^^^^^^^^^^^^^^^^^^^^^^^^^^^^^^^^^^^^^^^^^^^^^^^^^^^^^
socket.gaierror: [Errno -2] Name or service not known

The above exception was the direct cause of the following exception:

Traceback (most recent call last):
  File "/home/airflow/.local/lib/python3.12/site-packages/urllib3/connectionpool.py", line 793, in urlopen
    response = self._make_request(
               ^^^^^^^^^^^^^^^^^^^
  File "/home/airflow/.local/lib/python3.12/site-packages/urllib3/connectionpool.py", line 491, in _make_request
    raise new_e
  File "/home/airflow/.local/lib/python3.12/site-packages/urllib3/connectionpool.py", line 467, in _make_request
    self._validate_conn(conn)
  File "/home/airflow/.local/lib/python3.12/site-packages/urllib3/connectionpool.py", line 1099, in _validate_conn
    conn.connect()
  File "/home/airflow/.local/lib/python3.12/site-packages/urllib3/connection.py", line 616, in connect
    self.sock = sock = self._new_conn()
                       ^^^^^^^^^^^^^^^^
  File "/home/airflow/.local/lib/python3.12/site-packages/urllib3/connection.py", line 205, in _new_conn
    raise NameResolutionError(self.host, self, e) from e
urllib3.exceptions.NameResolutionError: <urllib3.connection.HTTPSConnection object at 0x7eff72ff0140>: Failed to resolve 'api.elsevier.com' ([Errno -2] Name or service not known)

The above exception was the direct cause of the following exception:

Traceback (most recent call last):
  File "/home/airflow/.local/lib/python3.12/site-packages/requests/adapters.py", line 486, in send
    resp = conn.urlopen(
           ^^^^^^^^^^^^^
  File "/home/airflow/.local/lib/python3.12/site-packages/urllib3/connectionpool.py", line 847, in urlopen
    retries = retries.increment(
              ^^^^^^^^^^^^^^^^^^
  File "/home/airflow/.local/lib/python3.12/site-packages/urllib3/util/retry.py", line 515, in increment
    raise MaxRetryError(_pool, url, reason) from reason  # type: ignore[arg-type]
    ^^^^^^^^^^^^^^^^^^^^^^^^^^^^^^^^^^^^^^^^^^^^^^^^^^^
urllib3.exceptions.MaxRetryError: HTTPSConnectionPool(host='api.elsevier.com', port=443): Max retries exceeded with url: /content/search/scopus?query=%28PUBYEAR%20%3D%202018%29%20AND%20%28DOCTYPE%28ar%29%29&count=20&start=20 (Caused by NameResolutionError("<urllib3.connection.HTTPSConnection object at 0x7eff72ff0140>: Failed to resolve 'api.elsevier.com' ([Errno -2] Name or service not known)"))

During handling of the above exception, another exception occurred:

Traceback (most recent call last):
  File "/home/airflow/.local/lib/python3.12/site-packages/airflow/models/taskinstance.py", line 465, in _execute_task
    result = _execute_callable(context=context, **execute_callable_kwargs)
             ^^^^^^^^^^^^^^^^^^^^^^^^^^^^^^^^^^^^^^^^^^^^^^^^^^^^^^^^^^^^^
  File "/home/airflow/.local/lib/python3.12/site-packages/airflow/models/taskinstance.py", line 432, in _execute_callable
    return execute_callable(context=context, **execute_callable_kwargs)
           ^^^^^^^^^^^^^^^^^^^^^^^^^^^^^^^^^^^^^^^^^^^^^^^^^^^^^^^^^^^^
  File "/home/airflow/.local/lib/python3.12/site-packages/airflow/models/baseoperator.py", line 400, in wrapper
    return func(self, *args, **kwargs)
           ^^^^^^^^^^^^^^^^^^^^^^^^^^^
  File "/home/airflow/.local/lib/python3.12/site-packages/airflow/operators/python.py", line 235, in execute
    return_value = self.execute_callable()
                   ^^^^^^^^^^^^^^^^^^^^^^^
  File "/home/airflow/.local/lib/python3.12/site-packages/airflow/operators/python.py", line 252, in execute_callable
    return self.python_callable(*self.op_args, **self.op_kwargs)
           ^^^^^^^^^^^^^^^^^^^^^^^^^^^^^^^^^^^^^^^^^^^^^^^^^^^^^
  File "/opt/airflow/dags/test_dags.py", line 34, in scraping
    paper_info_path , ref_info_path = get_scraping()
                                      ^^^^^^^^^^^^^^
  File "/opt/airflow/dags/scraping.py", line 135, in get_scraping
    response = rq.get(api_url + search_query +"&count="+itemperpage  + "&start=" +str(int(itemperpage) *days_fetch) , headers = header)
               ^^^^^^^^^^^^^^^^^^^^^^^^^^^^^^^^^^^^^^^^^^^^^^^^^^^^^^^^^^^^^^^^^^^^^^^^^^^^^^^^^^^^^^^^^^^^^^^^^^^^^^^^^^^^^^^^^^^^^^^^
  File "/home/airflow/.local/lib/python3.12/site-packages/requests/api.py", line 73, in get
    return request("get", url, params=params, **kwargs)
           ^^^^^^^^^^^^^^^^^^^^^^^^^^^^^^^^^^^^^^^^^^^^
  File "/home/airflow/.local/lib/python3.12/site-packages/requests/api.py", line 59, in request
    return session.request(method=method, url=url, **kwargs)
           ^^^^^^^^^^^^^^^^^^^^^^^^^^^^^^^^^^^^^^^^^^^^^^^^^
  File "/home/airflow/.local/lib/python3.12/site-packages/requests/sessions.py", line 589, in request
    resp = self.send(prep, **send_kwargs)
           ^^^^^^^^^^^^^^^^^^^^^^^^^^^^^^
  File "/home/airflow/.local/lib/python3.12/site-packages/requests/sessions.py", line 703, in send
    r = adapter.send(request, **kwargs)
        ^^^^^^^^^^^^^^^^^^^^^^^^^^^^^^^
  File "/home/airflow/.local/lib/python3.12/site-packages/requests/adapters.py", line 519, in send
    raise ConnectionError(e, request=request)
requests.exceptions.ConnectionError: HTTPSConnectionPool(host='api.elsevier.com', port=443): Max retries exceeded with url: /content/search/scopus?query=%28PUBYEAR%20%3D%202018%29%20AND%20%28DOCTYPE%28ar%29%29&count=20&start=20 (Caused by NameResolutionError("<urllib3.connection.HTTPSConnection object at 0x7eff72ff0140>: Failed to resolve 'api.elsevier.com' ([Errno -2] Name or service not known)"))
[2024-05-10T02:52:00.967+0000] {taskinstance.py:1206} INFO - Marking task as FAILED. dag_id=test_project, task_id=scraping_data, run_id=scheduled__2024-05-08T23:00:00+00:00, execution_date=20240508T230000, start_date=20240510T025200, end_date=20240510T025200
[2024-05-10T02:52:00.979+0000] {standard_task_runner.py:110} ERROR - Failed to execute job 14 for task scraping_data (HTTPSConnectionPool(host='api.elsevier.com', port=443): Max retries exceeded with url: /content/search/scopus?query=%28PUBYEAR%20%3D%202018%29%20AND%20%28DOCTYPE%28ar%29%29&count=20&start=20 (Caused by NameResolutionError("<urllib3.connection.HTTPSConnection object at 0x7eff72ff0140>: Failed to resolve 'api.elsevier.com' ([Errno -2] Name or service not known)")); 376)
[2024-05-10T02:52:00.998+0000] {local_task_job_runner.py:240} INFO - Task exited with return code 1
[2024-05-10T02:52:01.016+0000] {taskinstance.py:3498} INFO - 0 downstream tasks scheduled from follow-on schedule check
[2024-05-10T02:52:01.017+0000] {local_task_job_runner.py:222} INFO - ::endgroup::
