[2024-05-10T10:12:03.772+0000] {local_task_job_runner.py:120} INFO - ::group::Pre task execution logs
[2024-05-10T10:13:06.696+0000] {taskinstance.py:2076} INFO - Dependencies all met for dep_context=non-requeueable deps ti=<TaskInstance: ds_project.ds_task manual__2024-05-10T10:11:01.185359+00:00 [queued]>
[2024-05-10T10:13:21.200+0000] {taskinstance.py:2076} INFO - Dependencies all met for dep_context=requeueable deps ti=<TaskInstance: ds_project.ds_task manual__2024-05-10T10:11:01.185359+00:00 [queued]>
[2024-05-10T10:13:22.429+0000] {taskinstance.py:2306} INFO - Starting attempt 1 of 1
[2024-05-10T10:13:34.478+0000] {taskinstance.py:2330} INFO - Executing <Task(PythonOperator): ds_task> on 2024-05-10 10:11:01.185359+00:00
[2024-05-10T10:13:38.827+0000] {standard_task_runner.py:90} INFO - Running: ['***', 'tasks', 'run', 'ds_project', 'ds_task', 'manual__2024-05-10T10:11:01.185359+00:00', '--job-id', '47', '--raw', '--subdir', 'DAGS_FOLDER/test_dags.py', '--cfg-path', '/tmp/tmp1oa7n1cm']
[2024-05-10T10:13:38.819+0000] {logging_mixin.py:188} WARNING - /home/***/.local/lib/python3.12/site-packages/***/task/task_runner/standard_task_runner.py:61 DeprecationWarning: This process (pid=825) is multi-threaded, use of fork() may lead to deadlocks in the child.
[2024-05-10T10:13:38.878+0000] {standard_task_runner.py:91} INFO - Job 47: Subtask ds_task
[2024-05-10T10:13:38.883+0000] {standard_task_runner.py:63} INFO - Started process 845 to run task
[2024-05-10T10:13:54.571+0000] {task_command.py:426} INFO - Running <TaskInstance: ds_project.ds_task manual__2024-05-10T10:11:01.185359+00:00 [running]> on host 3514ccd847da
[2024-05-10T10:13:55.067+0000] {taskinstance.py:2648} INFO - Exporting env vars: AIRFLOW_CTX_DAG_OWNER='***' AIRFLOW_CTX_DAG_ID='ds_project' AIRFLOW_CTX_TASK_ID='ds_task' AIRFLOW_CTX_EXECUTION_DATE='2024-05-10T10:11:01.185359+00:00' AIRFLOW_CTX_TRY_NUMBER='1' AIRFLOW_CTX_DAG_RUN_ID='manual__2024-05-10T10:11:01.185359+00:00'
[2024-05-10T10:13:55.074+0000] {taskinstance.py:430} INFO - ::endgroup::
[2024-05-10T10:13:55.281+0000] {logging_mixin.py:188} INFO - Start
[2024-05-10T10:13:55.361+0000] {taskinstance.py:441} INFO - ::group::Post task execution logs
[2024-05-10T10:13:55.372+0000] {taskinstance.py:2905} ERROR - Task failed with exception
Traceback (most recent call last):
  File "/home/airflow/.local/lib/python3.12/site-packages/airflow/models/taskinstance.py", line 465, in _execute_task
    result = _execute_callable(context=context, **execute_callable_kwargs)
             ^^^^^^^^^^^^^^^^^^^^^^^^^^^^^^^^^^^^^^^^^^^^^^^^^^^^^^^^^^^^^
  File "/home/airflow/.local/lib/python3.12/site-packages/airflow/models/taskinstance.py", line 432, in _execute_callable
    return execute_callable(context=context, **execute_callable_kwargs)
           ^^^^^^^^^^^^^^^^^^^^^^^^^^^^^^^^^^^^^^^^^^^^^^^^^^^^^^^^^^^^
  File "/home/airflow/.local/lib/python3.12/site-packages/airflow/models/baseoperator.py", line 400, in wrapper
    return func(self, *args, **kwargs)
           ^^^^^^^^^^^^^^^^^^^^^^^^^^^
  File "/home/airflow/.local/lib/python3.12/site-packages/airflow/operators/python.py", line 235, in execute
    return_value = self.execute_callable()
                   ^^^^^^^^^^^^^^^^^^^^^^^
  File "/home/airflow/.local/lib/python3.12/site-packages/airflow/operators/python.py", line 252, in execute_callable
    return self.python_callable(*self.op_args, **self.op_kwargs)
           ^^^^^^^^^^^^^^^^^^^^^^^^^^^^^^^^^^^^^^^^^^^^^^^^^^^^^
  File "/opt/airflow/dags/test_dags.py", line 45, in ds_run_script
    main(paper_info_path, ref_info_path)
  File "/opt/airflow/dags/script.py", line 226, in main
    df_ref, df_pub, lat_lon_ciry = load_data()
                                   ^^^^^^^^^^^
  File "/opt/airflow/dags/script.py", line 157, in load_data
    lat_lon_ciry = pd.read_csv(get_path("/data_raw/worldcities.csv"))
                   ^^^^^^^^^^^^^^^^^^^^^^^^^^^^^^^^^^^^^^^^^^^^^^^^^^
  File "/home/airflow/.local/lib/python3.12/site-packages/pandas/io/parsers/readers.py", line 1026, in read_csv
    return _read(filepath_or_buffer, kwds)
           ^^^^^^^^^^^^^^^^^^^^^^^^^^^^^^^
  File "/home/airflow/.local/lib/python3.12/site-packages/pandas/io/parsers/readers.py", line 620, in _read
    parser = TextFileReader(filepath_or_buffer, **kwds)
             ^^^^^^^^^^^^^^^^^^^^^^^^^^^^^^^^^^^^^^^^^^
  File "/home/airflow/.local/lib/python3.12/site-packages/pandas/io/parsers/readers.py", line 1620, in __init__
    self._engine = self._make_engine(f, self.engine)
                   ^^^^^^^^^^^^^^^^^^^^^^^^^^^^^^^^^
  File "/home/airflow/.local/lib/python3.12/site-packages/pandas/io/parsers/readers.py", line 1880, in _make_engine
    self.handles = get_handle(
                   ^^^^^^^^^^^
  File "/home/airflow/.local/lib/python3.12/site-packages/pandas/io/common.py", line 873, in get_handle
    handle = open(
             ^^^^^
FileNotFoundError: [Errno 2] No such file or directory: '/data_raw/worldcities.csv'
[2024-05-10T10:13:55.483+0000] {taskinstance.py:1206} INFO - Marking task as FAILED. dag_id=ds_project, task_id=ds_task, run_id=manual__2024-05-10T10:11:01.185359+00:00, execution_date=20240510T101101, start_date=20240510T101307, end_date=20240510T101355
[2024-05-10T10:13:55.518+0000] {standard_task_runner.py:110} ERROR - Failed to execute job 47 for task ds_task ([Errno 2] No such file or directory: '/data_raw/worldcities.csv'; 845)
[2024-05-10T10:13:55.722+0000] {local_task_job_runner.py:240} INFO - Task exited with return code 1
[2024-05-10T10:13:55.809+0000] {taskinstance.py:3498} INFO - 0 downstream tasks scheduled from follow-on schedule check
[2024-05-10T10:13:55.822+0000] {local_task_job_runner.py:222} INFO - ::endgroup::
